Workbook

Sheet Evaluation
A2: Department: Quality Assurance | E2: Procedure title: Slaughtering Checklist | I2: Effective date: 1-1-2019
A3: Documents code: QP-23-FM-01 | E3: Prepared by: Mostafa Esmail | I3: Prepared date: 1-1-2019
A4: Version: 1 | E4: Reviewed by: Abd El Hadi Mohamed | I4: Reviewed date: 1-1-2019
A5: Edition: 0/5 | E5: Approved by: Mr. Mohamed Seoudi | I5: Approved date: 1-1-2019
A7: Slaughtering Information:
B8: Date: | D8: 46278
B9: Farm: | D9: Family | G9: Location: | I9: fayoum
B10: Slaughterhouse: | D10: Al Salam | G10: Location: | I10: Cairo
B11: Animal type: | D11: Native breed bulls | G11: Trip duration: | I11: 2 hours
B12: Number: | D12: 68
B13: Received: | D13: 66 | G13: Exception | I13: 0
B14: Rejected: | D14: =D12-D13 -> 2 | G14: Exception % | I14: =I13/D13 -> 0
B15: Farm weight: | D15: 28943 | G15: Av. farm weight: | I15: =D15/D12 -> 425.63235
B16: Receiving weight: | D16: 28943 | G16: Av. receiving weight: | I16: =D16/D12 -> 425.63235
B17: Rejected weight: | D17: 0 | G17: Av. rejected weight: | I17: =D17/D14 -> 0
B18: Transportation loss: | D18: =D15-D16 -> 0 | G18: Trans. Loss %: | I18: =D18/D15 -> 0
B19: Carcass weight: | D19: 17540 | G19: Av.carcass weight: | I19: =D19/D13 -> 265.75758
B20: Fat weight: | D20: 410 | G20: Av. Fat weight: | I20: =D20/D13 -> 6.2121212
B21: Condemnation: | D21: 4 livers - 1 flank - 12 kidneys - 1 heart - 3 lungs - 1 spleen | G21: Total cond. weight: | I21: 0
A24: Chilled trucks:
B25: Truck number | D25: Departure temp. | G25: Truck number | I25: Departure temp.
B26: 1363 | D26: 18 | G26: 3642 | I26: 20 ℃
B27: 2578 | D27: 22 | G27: 5236 | I27: 19
B28: 1361 | D28: 21 ℃ | G28: 8356 | I28: 20
A31: Key Performance Indicators (KPIs):
D32: Slaughtering evaluation | G32: =Checklist!D59 -> 0.89030303
D33: AM & PM examination | G33: =AVERAGE((Checklist!D14/25),(Checklist!D44/50)) -> 0.95530303
D34: Transportation loss | G34: =I18 -> 0
D35: Dressing | G35: =D19/D15 -> 0.60601873
A37: Important slaughtering notes:
A38: 1. Rejection of:
A39: 1. 1 carcass due to Sarcocystic eosinophilic myositis.
A40: 2. ⁠1 carcass due to generalized pyemia.
A41: 2. Trimming of:
A42: 1. Injection sites in 10 carcasses.
A43: 2. Bruises in 1 carcass.
A44: 3. Abscesses in 25 carcasses.
A45: 3. Condemnation of:
A46: 1. 4 livers due to telangiectasis, abscesses and Fasciola.
A47: 2. 1 Flank due to TB.
...

Sheet Checklist
A1: Meat quality checklist
A2: 1. Ante-mortem examination: | B2: Total | C2: nonconformity | D2: Degree | E2: Notes
A3: Transportation truck:
A4: Rough handling: | B4: 5 | D4: =(Evaluation!D13-Checklist!C4)/Evaluation!D13*Checklist!B4 -> 5
A5: Over capacity: | B5: 5 | D5: =(Evaluation!D13-Checklist!C5)/Evaluation!D13*Checklist!B5 -> 5
A6: Animal identification: | B6: 1 | D6: =(Evaluation!D13-Checklist!C6)/Evaluation!D13*Checklist!B6 -> 1
A7: Age | B7: 5 | D7: =(Evaluation!D13-Checklist!C7)/Evaluation!D13*Checklist!B7 -> 5
A8: Animals hygienic conditions | B8: 3 | D8: =(Evaluation!D13-Checklist!C8)/Evaluation!D13*Checklist!B8 -> 3
A9: General health condition: | B9: 1 | D9: 1
A10: Lymph nodes | B10: 1 | D10: 1
A11: Skin diseases | B11: 1 | D11: =(Evaluation!D13-Checklist!C11)/Evaluation!D13*Checklist!B11 -> 1
A12: External parasites | B12: 1 | D12: =(Evaluation!D13-Checklist!C12)/Evaluation!D13*Checklist!B12 -> 1
A13: Body condition scores | B13: 2 | D13: =(Evaluation!D13-Checklist!C13)/Evaluation!D13*Checklist!B13 -> 2
B14: Total: | D14: =SUM(D4:D13) -> 25
A16: 2. Slaughterhouse hygienic condition: | B16: 5
A17: Facilities | B17: 1 | D17: 0
A18: Tools | B18: 2 | D18: 0
A19: Employee | B19: 2 | D19: 0
B20: Total: | D20: =SUM(D17:D19) -> 0
A22: 3. Post mortem examination: | B22: 50
A23: Proper killing: | B23: 3 | D23: =(Evaluation!D13-Checklist!C23)/Evaluation!D13*Checklist!B23 -> 3
A24: Completely dead before cutting spinal cord: | B24: 3 | D24: =(Evaluation!D13-Checklist!C24)/Evaluation!D13*Checklist!B24 -> 3
A25: Bleeding: | B25: 5 | D25: =(Evaluation!D13-Checklist!C25)/Evaluation!D13*Checklist!B25 -> 5
A26: Flaying process: | B26: 1 | D26: =(Evaluation!D13-Checklist!C26)/Evaluation!D13*Checklist!B26 -> 1
A27: Bruises: | B27: 5 | C27: 36 | D27: =(Evaluation!D13-Checklist!C27)/Evaluation!D13*Checklist!B27 -> 2.2727273 | E27: Injection site blemishes - abscesses - bruises
A28: Evisceration efficacy:
A29: Urinary bladder: | B29: 1 | D29: =(Evaluation!D13-Checklist!C29)/Evaluation!D13*Checklist!B29 -> 1
A30: Intestine: | B30: 1 | D30: =(Evaluation!D13-Checklist!C30)/Evaluation!D13*Checklist!B30 -> 1
A31: Rumen: | B31: 2 | C31: 1 | D31: =(Evaluation!D13-Checklist!C31)/Evaluation!D13*Checklist!B31 -> 1.969697 | E31: splenomegaly
A32: Gall bladder: | B32: 1 | D32: =(Evaluation!D13-Checklist!C32)/Evaluation!D13*Checklist!B32 -> 1
A33: Examination of cacass L.N.: | B33: 5 | C33: 1 | D33: =(Evaluation!D13-Checklist!C33)/Evaluation!D13*Checklist!B33 -> 4.9242424 | E33: tb
A34: Examination of head: | B34: 1 | D34: =(Evaluation!D13-Checklist!C34)/Evaluation!D13*Checklist!B34 -> 1
A35: Examination of organs:
A36: lung: | B36: 2 | C36: 3 | D36: =(Evaluation!D13-Checklist!C36)/Evaluation!D13*Checklist!B36 -> 1.9090909 | E36: pneumonia
A37: Liver: | B37: 2 | C37: 4 | D37: =(Evaluation!D13-Checklist!C37)/Evaluation!D13*Checklist!B37 -> 1.8787879 | E37: abscesses
A38: Kidney: | B38: 2 | C38: 6 | D38: =(Evaluation!D13-Checklist!C38)/Evaluation!D13*Checklist!B38 -> 1.8181818 | E38: hydronephrosis
A39: Heart: | B39: 2 | C39: 1 | D39: =(Evaluation!D13-Checklist!C39)/Evaluation!D13*Checklist!B39 -> 1.969697 | E39: pericarditis
A40: Jaundice: | B40: 3 | D40: =(Evaluation!D13-Checklist!C40)/Evaluation!D13*Checklist!B40 -> 3
A41: Contamination: | B41: 5 | D41: =(Evaluation!D13-Checklist!C41)/Evaluation!D13*Checklist!B41 -> 5
A42: Condemnation: | B42: 5 | C42: 16 | D42: =(Evaluation!D13-Checklist!C42)/Evaluation!D13*Checklist!B42 -> 3.7878788 | E42: 4 livers - 1 flank - 12 kidneys - 1 heart - 3 lungs - 1 spleen
...

Sheet Related pictures
